<?xml version="1.0"?>

<!-- define xacro as the namespace referencing the xacro format. Important for compiling xacro files and macros-->
<robot xmlns:xacro="http://www.ros.org/wiki/xacro">

<!-- Macro detailing the details of each wheel -->
<xacro:macro name="wheel" params="prefix parent wheelrad wheeldepth wheelkg *origin *inertia">

    <!-- Create a link for the wheels -->
    <link name="${prefix}_wheel_link">
        <visual>
            <!-- Set origin to be rotated 90 degrees to have base on ground -->
            <origin xyz="0 0 0" rpy="${PI/2} 0 0"/>
            <geometry>
                <cylinder radius="${wheelrad}" length="${wheeldepth}"/>
            </geometry>
        </visual>

        <collision>
            <origin xyz="0 0 0" rpy="${PI/2} 0 0"/>
            <geometry>
                <cylinder radius="${wheelrad}" length="${wheeldepth}"/>
            </geometry>
        </collision>

        <!-- Inertial values are required for Gazebo -->
        <inertial>
            <origin xyz="0 0 0" rpy="0 0 0"/>
            <mass value="${wheelkg}"/>
            <xacro:insert_block name="inertia"/>
        </inertial>
    </link>

    <joint name="${prefix}_wheel" type="continuous">
        <parent link="${parent}"/>
        <child link="${prefix}_wheel_link"/>

        <!-- 
            Use insert_block to specify joint (and wheel) position in wheel declaration
        -->
        <xacro:insert_block name="origin"/>

        <!-- Specify rotation axis of wheel -->
        <axis xyz="0 1 0"/>
    </joint>

    <!-- Transission for Gazebo -->
    <transmission name="${prefix}_wheel_trans">
        <type>transmission_interface/SimpleTransmission</type>
        <!-- 
            Reference the joint in Gazebo. We want a velocity interface here,
            as we want to be able to control the speed of the rover.
        -->
        <joint name="${prefix}_wheel">
            <hardwareInterface>hardware_interface/VelocityJointInterface</hardwareInterface>
        </joint>
        <actuator name="${prefix}_actuator">
            <hardwareInterface>hardware_interface/VelocityJointInterface</hardwareInterface>
            <mechanicalreduction>1</mechanicalreduction>
        </actuator>
    </transmission>

</xacro:macro>

</robot>