<?xml version="1.0"?>

<!-- define xacro as the namespace referencing the xacro format. Important for compiling xacro files and macros-->
<robot xmlns:xacro="http://www.ros.org/wiki/xacro">

<!-- Description for a simple rocker bar. Could also be used as a bogie? -->
<xacro:macro name="rocker" params="prefix parent rockerx rockery rockerz rockerkg *origin">

    <!-- Create a link for the wheels -->
    <link name="${prefix}_rocker_link">
        <visual>
            <!-- Set origin to be rotated 90 degrees to have base on ground -->
            <origin xyz="0 0 0" rpy="0 0 0"/>
            <geometry>
                <box size="${rockerx} ${rockery} ${rockerz}"/>
            </geometry>
        </visual>

        <collision>
            <origin xyz="0 0 0" rpy="0 0 0"/>
            <geometry>
                <box size="${rockerx} ${rockery} ${rockerz}"/>
            </geometry>
        </collision>

        <!-- Inertial and mass values are required for Gazebo, but they do not need to be accurate for most applications -->
        <inertial>
            <origin xyz="0 0 0" rpy="0 0 0"/>
            <mass value="${rockerkg}"/>
            <inertia ixx="0.001" ixy="0" ixz="0"
                        iyy="0.001" iyz="0" izz="0.001" />
        </inertial>
    </link>

    <joint name="${prefix}_rocker_joint" type="continuous">
        <parent link="${parent}"/>
        <child link="${prefix}_rocker_link"/>

        <!-- 
            Use insert_block to specify joint (and wheel) position in wheel declaration
        -->
        <xacro:insert_block name="origin"/>

        <!-- Specify rotation axis of wheel -->
        <axis xyz="0 1 0"/>
    </joint>

</xacro:macro>

</robot>